# Comprehensive Robustness Analysis - Per-Response Metrics Storage

**Date:** 2025-10-23
**Scope:** `_store_single_response_metric_sync()` method in `job_processor.py`
**Status:** 🔍 CRITICAL ISSUES IDENTIFIED

---

## Executive Summary

Identified **12 critical issues** in the per-response metrics extraction and storage pipeline that could cause:
- Data corruption (double JSON encoding)
- Silent failures (type mismatches)
- Calculation errors (NULL handling)
- Data loss (precision loss)
- Difficult debugging (poor error logging)

---

## Issue #1: 🔴 CRITICAL - Numeric Range Validation Missing

**Location:** Lines 2082-2115
**Risk:** Database constraint violations, incorrect calculations

### Problem
No validation that LLM-provided scores are within expected 0-100 range.

**What can go wrong:**
```python
# LLM hallucination or bug returns invalid values
citation_quality = geo_factors.get('citation_quality', 0)  # Could be 9999 or -50
geo_score = (9999 + 0 + 0 + 0) / 4.0  # = 2499.75 ❌

# DB column is numeric(5,2) with max 999.99
# Values > 999.99 will cause: "numeric field overflow" error
```

**Impact:**
- ✅ Database insertion fails (good - prevents bad data)
- ❌ Entire metric update lost (bad - no partial save)
- ❌ No logging of which value caused failure (bad - hard to debug)

### Fix Required
```python
def _validate_score(value: Any, field_name: str, min_val: float = 0, max_val: float = 100) -> float:
    """Validate and clamp score to valid range"""
    try:
        score = float(value) if value is not None else 0
        if score < min_val or score > max_val:
            logger.warning(f"Score '{field_name}' out of range: {score} (clamping to {min_val}-{max_val})")
            score = max(min_val, min(max_val, score))
        return score
    except (TypeError, ValueError) as e:
        logger.error(f"Invalid score type for '{field_name}': {value} ({type(value)})")
        return 0.0

# Apply to all scores
citation_quality = _validate_score(geo_factors.get('citation_quality', 0), 'citation_quality')
geo_score = _validate_score(geo_score, 'geo_score')
sov_score = _validate_score(sov_score, 'sov_score', max_val=100)
```

---

## Issue #2: 🟡 MEDIUM - NULL/None Handling in Calculations

**Location:** Lines 2088, 2096, 2115
**Risk:** TypeError exceptions, calculation failures

### Problem
Arithmetic operations with None values will raise TypeError.

**What can go wrong:**
```python
# If LLM returns None or omits a field
citation_quality = geo_factors.get('citation_quality', 0)  # Returns 0 if missing ✅
# But if LLM explicitly returns null:
geo_factors = {'citation_quality': None, ...}
citation_quality = geo_factors.get('citation_quality', 0)  # Returns None! ❌

geo_score = (None + 0 + 0 + 0) / 4.0  # TypeError: unsupported operand type(s)
```

**Impact:**
- ❌ Exception raised
- ❌ Entire metric update fails
- ❌ Error logged but no recovery

### Fix Required
```python
# Safe extraction with type coercion
def _safe_get_number(d: dict, key: str, default: float = 0) -> float:
    """Safely extract numeric value from dict, handling None/null"""
    value = d.get(key, default)
    if value is None:
        return default
    try:
        return float(value)
    except (TypeError, ValueError):
        logger.warning(f"Non-numeric value for '{key}': {value}")
        return default

citation_quality = _safe_get_number(geo_factors, 'citation_quality', 0)
```

---

## Issue #3: 🔴 CRITICAL - Array Type Validation Missing

**Location:** Line 2166
**Risk:** TypeError on non-list values

### Problem
Concatenating arrays without type checking.

**What can go wrong:**
```python
specific_features = features_value_props.get('features_mentioned', [])  # Could be None or string
value_props = features_value_props.get('value_props_highlighted', [])  # Could be None

# If LLM returns null or wrong type:
specific_features = None
value_props = []
combined = specific_features + value_props  # TypeError: unsupported operand type(s) for +: 'NoneType' and 'list'
```

**Impact:**
- ❌ Exception raised
- ❌ Entire metric update fails

### Fix Required
```python
def _ensure_list(value: Any) -> list:
    """Ensure value is a list"""
    if value is None:
        return []
    if isinstance(value, list):
        return value
    if isinstance(value, str):
        return [value]  # Single string -> single-item list
    logger.warning(f"Unexpected type for list field: {type(value)}")
    return []

specific_features = _ensure_list(features_value_props.get('features_mentioned', []))
value_props = _ensure_list(features_value_props.get('value_props_highlighted', []))
combined = specific_features + value_props
```

---

## Issue #4: 🟡 MEDIUM - Array Length Limits

**Location:** Line 2166, 2190, 2191
**Risk:** Database performance degradation, JSONB size limits

### Problem
No limit on array sizes - LLM could return 1000 features.

**PostgreSQL Limits:**
- JSONB max size: ~1GB (theoretical)
- Practical limit: ~100MB (performance degradation)
- Index size impacts query performance

**What can go wrong:**
```python
# LLM goes wild
specific_features = ['feature1', 'feature2', ..., 'feature9999']  # 9999 items!
combined = specific_features + value_props  # 10000+ items in one array

# Database impact:
# - Slow INSERT/UPDATE
# - Slow queries with JSONB indexing
# - Slow frontend rendering
```

### Fix Required
```python
MAX_ARRAY_ITEMS = 50  # Reasonable limit

def _limit_array(arr: list, max_items: int = MAX_ARRAY_ITEMS, field_name: str = '') -> list:
    """Limit array size and log if truncated"""
    if len(arr) > max_items:
        logger.warning(f"Array '{field_name}' truncated: {len(arr)} items -> {max_items} items")
        return arr[:max_items]
    return arr

specific_features = _limit_array(specific_features, field_name='features_mentioned')
combined = _limit_array(combined, field_name='key_features_mentioned')
```

---

## Issue #5: 🟡 MEDIUM - String Length Validation

**Location:** Lines 2130, 2131, 2132, 2148
**Risk:** Database constraint violations

### Problem
No validation on string field lengths.

**Schema constraints:**
```sql
mention_context VARCHAR(50)
sentiment VARCHAR(20)
recommendation_strength VARCHAR(20)
context_quality VARCHAR(20)
buyer_journey_category VARCHAR(50)
```

**What can go wrong:**
```python
# LLM returns verbose text
context_quality = "This is an exceptionally high quality mention with extensive detail..."  # 80 chars
# DB column is VARCHAR(20) -> truncated or error
```

**Impact:**
- PostgreSQL behavior: Silently truncates to column length (if no constraint)
- Or raises: "value too long for type character varying(20)"

### Fix Required
```python
def _truncate_string(value: str, max_length: int, field_name: str = '') -> str:
    """Truncate string to max length and log if needed"""
    if value and len(value) > max_length:
        logger.warning(f"String '{field_name}' truncated: {len(value)} chars -> {max_length} chars")
        return value[:max_length]
    return value if value else ''

mention_context = _truncate_string(context_quality, 50, 'mention_context')
sentiment = _truncate_string(sentiment, 20, 'sentiment')
context_quality = _truncate_string(context_quality, 20, 'context_quality')
```

---

## Issue #6: 🔴 CRITICAL - Structure Quality Edge Cases

**Location:** Lines 2110-2111
**Risk:** Silent data corruption with unexpected values

### Problem
Dictionary lookup with default hides invalid values.

**What can go wrong:**
```python
structure_quality_str = seo_positioning.get('structure_quality', 'fair')  # Returns 'fair' if missing
# But what if LLM returns invalid value?
structure_quality_str = 'excellent'  # Not in mapping!
structure_quality = {'good': 85, 'fair': 50, 'poor': 20}.get('excellent', 50)  # Returns 50

# Result: "excellent" quality becomes "fair" (50) with no warning ❌
```

**Valid LLM values:** "good", "fair", "poor"
**Actual LLM might return:** "excellent", "bad", "average", "high", "low", null, etc.

### Fix Required
```python
STRUCTURE_QUALITY_MAPPING = {
    'good': 85,
    'excellent': 85,  # Alias
    'high': 85,       # Alias
    'fair': 50,
    'average': 50,    # Alias
    'medium': 50,     # Alias
    'poor': 20,
    'bad': 20,        # Alias
    'low': 20         # Alias
}

structure_quality_str = seo_positioning.get('structure_quality', 'fair')
if structure_quality_str not in STRUCTURE_QUALITY_MAPPING:
    logger.warning(f"Unexpected structure_quality value: '{structure_quality_str}' (using 'fair')")
    structure_quality_str = 'fair'
structure_quality = STRUCTURE_QUALITY_MAPPING[structure_quality_str]
```

---

## Issue #7: 🟡 MEDIUM - JSON Encoding Validation

**Location:** Lines 2172-2183, 2190-2193
**Risk:** JSON encoding failures, double encoding

### Problem
No validation that dicts/lists are JSON-serializable.

**What can go wrong:**
```python
# LLM returns non-serializable objects (shouldn't happen, but...)
content_gaps = [datetime.now(), CustomObject()]  # Not JSON serializable!
json.dumps({'content_gaps': content_gaps})  # TypeError: Object of type datetime is not JSON serializable
```

**Also: Redundant encoding check needed**
```python
# Line 2193: Are we sure additional_metrics is still a dict and not already JSON string?
additional_metrics = metric.get('additional_metrics', {})  # Dict
# ... (no modifications)
json.dumps(additional_metrics)  # Should work, but verify type first
```

### Fix Required
```python
def _safe_json_dumps(obj: Any, field_name: str = '') -> str:
    """Safely JSON encode object with error handling"""
    try:
        # If already a string, validate it's valid JSON
        if isinstance(obj, str):
            json.loads(obj)  # Validate
            return obj
        # Encode with error handling
        return json.dumps(obj, default=str)  # default=str handles non-serializable types
    except (TypeError, ValueError) as e:
        logger.error(f"JSON encoding failed for '{field_name}': {e}")
        return '{}'  # Empty JSON object as fallback

analysis_metadata_json = _safe_json_dumps({...}, 'analysis_metadata')
features_json = _safe_json_dumps(specific_features, 'features_mentioned')
```

---

## Issue #8: 🔴 CRITICAL - Division by Zero Edge Case

**Location:** Line 2096 (SOV calculation)
**Risk:** Already handled with max(), but verify edge cases

### Current Code (GOOD)
```python
sov_score = (brand_mentions_in_response / max(total_brand_mentions, 1)) * 100.0
```

### Edge Cases to Verify
```python
# Case 1: Both zero
brand_mentions = 0, total = 0
sov = (0 / max(0, 1)) * 100 = 0 / 1 * 100 = 0 ✅

# Case 2: Mentions > Total (LLM error)
brand_mentions = 5, total = 3
sov = (5 / max(3, 1)) * 100 = 5/3 * 100 = 166.67 ❌ (> 100!)

# Case 3: Negative values (LLM hallucination)
brand_mentions = -1, total = 5
sov = (-1 / 5) * 100 = -20 ❌
```

### Fix Required
```python
# Add validation
brand_mentions_in_response = max(0, _safe_get_number(sov_data, 'brand_mentions', 0))
total_brand_mentions = max(1, _safe_get_number(sov_data, 'total_brand_mentions', 1))

# Clamp mentions to total (can't mention more than total brands)
brand_mentions_in_response = min(brand_mentions_in_response, total_brand_mentions)

sov_score = (brand_mentions_in_response / total_brand_mentions) * 100.0
sov_score = min(100.0, sov_score)  # Cap at 100
```

---

## Issue #9: 🟡 MEDIUM - Error Logging Insufficient

**Location:** Line 2002
**Risk:** Difficult debugging, lost context

### Current Code
```python
except Exception as e:
    logger.error(f"[{audit_id}] Error storing metric for response {response_id}: {e}")
```

### Problems
- ❌ No stack trace logged
- ❌ No actual metric data logged
- ❌ No indication of WHICH field caused failure

### Fix Required
```python
except Exception as e:
    logger.error(
        f"[{audit_id}] Error storing metric for response {response_id} "
        f"(batch {batch_num} pos {i}): {e}",
        exc_info=True  # Include full stack trace
    )
    # Log the problematic metric data (truncated for safety)
    metric_sample = str(metric)[:500] if metric else 'None'
    logger.error(f"[{audit_id}] Problematic metric data: {metric_sample}")
```

---

## Issue #10: 🟡 MEDIUM - Missing Required Fields Validation

**Location:** Lines 2046-2055
**Risk:** Silent failures with incorrect defaults

### Problem
No validation that critical fields exist in metric dict.

**What can go wrong:**
```python
# LLM returns completely empty response or wrong structure
metric = {}  # Empty!

# All extractions return defaults
brand_analysis = metric.get('brand_analysis', {})  # {}
brand_mentioned = brand_analysis.get('mentioned', False)  # False
# ... all fields get defaults

# Result: Response saved with all zeros/defaults, looks like "brand not mentioned"
# But actually LLM failed to analyze properly!
```

### Fix Required
```python
def _validate_metric_structure(metric: Dict[str, Any], response_id: str, audit_id: str) -> bool:
    """Validate metric has required fields"""
    required_fields = ['brand_analysis', 'geo_factors', 'sov_data']
    missing = [f for f in required_fields if f not in metric or not metric[f]]

    if missing:
        logger.error(
            f"[{audit_id}] Metric for response {response_id} missing required fields: {missing}"
        )
        return False
    return True

# At start of _store_single_response_metric_sync
if not _validate_metric_structure(metric, response_id, audit_id):
    raise ValueError(f"Invalid metric structure for response {response_id}")
```

---

## Issue #11: 🔴 CRITICAL - Response ID Not Found

**Location:** Line 2157 (WHERE id = %s)
**Risk:** Silent failures, UPDATE affects 0 rows

### Problem
UPDATE WHERE id = %s will succeed but update 0 rows if ID doesn't exist.

**What can go wrong:**
```python
# Wrong response_id passed (bug in mapping logic)
cursor.execute("UPDATE audit_responses SET ... WHERE id = %s", (..., wrong_id))
# Query succeeds, but rowcount = 0 ❌
# No error raised, metric silently lost!
```

### Fix Required
```python
cursor.execute("""UPDATE ... WHERE id = %s""", (..., response_id))

# Verify update succeeded
if cursor.rowcount == 0:
    logger.error(
        f"[{audit_id}] UPDATE failed: response_id {response_id} not found in database"
    )
    raise ValueError(f"Response ID {response_id} does not exist")

logger.debug(f"[{audit_id}] Successfully updated response {response_id}")
```

---

## Issue #12: 🟡 MEDIUM - Transaction Isolation Inefficiency

**Location:** Line 2043 (new connection per metric)
**Risk:** Performance degradation, connection pool exhaustion

### Current Behavior
Each metric update gets a new database connection:
```python
def _store_single_response_metric_sync(...):
    conn = self._get_db_connection_sync()  # New connection!
    try:
        # ... update one row
    finally:
        conn.close()
```

**For 138 responses:**
- 138 connection open/close cycles
- 138 separate transactions
- Overhead: ~5-10ms per connection

**Total overhead:** 690-1380ms wasted on connection management

### Analysis
**Why this design?**
- Isolation: One failure doesn't break others ✅
- Parallelization: Can run in thread pool ✅

**Tradeoffs:**
- ❌ Slower than batch update
- ❌ Connection pool pressure
- ✅ Better error isolation

### Optimization Options
```python
# Option A: Batch updates (faster but less isolation)
def _store_metrics_batch(metrics: List[Dict]):
    conn = self._get_db_connection_sync()
    try:
        for metric in metrics:
            # Update in same transaction
            # If one fails, all rollback
    finally:
        conn.close()

# Option B: Keep current design but use connection pooling (RECOMMENDED)
# Verify connection pool is configured in _get_db_connection_sync()

# Option C: Use executemany() for true batch insert
cursor.executemany("UPDATE ...", [(...)  for m in metrics])
```

**Recommendation:** Keep current design if connection pool is properly configured. The isolation is worth the overhead.

---

## Summary of Issues

| # | Severity | Issue | Impact | Lines |
|---|----------|-------|--------|-------|
| 1 | 🔴 CRITICAL | No numeric range validation | DB errors, bad data | 2082-2115 |
| 2 | 🟡 MEDIUM | NULL handling in calculations | TypeErrors | 2088, 2096 |
| 3 | 🔴 CRITICAL | Array type validation missing | TypeErrors | 2166 |
| 4 | 🟡 MEDIUM | No array length limits | Performance issues | 2166, 2190 |
| 5 | 🟡 MEDIUM | String length validation missing | DB truncation | 2130-2148 |
| 6 | 🔴 CRITICAL | Structure quality edge cases | Silent data corruption | 2110-2111 |
| 7 | 🟡 MEDIUM | JSON encoding validation | Encoding errors | 2172-2193 |
| 8 | 🔴 CRITICAL | SOV > 100% possible | Incorrect metrics | 2096 |
| 9 | 🟡 MEDIUM | Insufficient error logging | Hard to debug | 2002 |
| 10 | 🟡 MEDIUM | No required fields validation | Silent failures | 2046-2055 |
| 11 | 🔴 CRITICAL | UPDATE 0 rows not detected | Lost data | 2157 |
| 12 | 🟡 MEDIUM | Connection per update overhead | Performance | 2043 |

**Total:** 12 issues (6 critical, 6 medium)

---

## Recommended Actions

### Priority 1 (CRITICAL - Fix Now)
1. ✅ Add numeric range validation (Issue #1)
2. ✅ Add array type validation (Issue #3)
3. ✅ Fix structure quality mapping (Issue #6)
4. ✅ Add SOV clamping (Issue #8)
5. ✅ Check UPDATE rowcount (Issue #11)

### Priority 2 (IMPORTANT - Fix Soon)
6. ✅ Add NULL handling (Issue #2)
7. ✅ Improve error logging (Issue #9)
8. ✅ Add required fields validation (Issue #10)

### Priority 3 (NICE TO HAVE)
9. Add array length limits (Issue #4)
10. Add string length validation (Issue #5)
11. Add JSON encoding validation (Issue #7)
12. Verify connection pooling (Issue #12)

---

## Next Steps

1. Create helper functions for validation/sanitization
2. Apply fixes to `_store_single_response_metric_sync()`
3. Add comprehensive unit tests
4. Test with intentionally malformed LLM responses
5. Monitor production logs for validation warnings
